Internal Server Error: /chipin/group/6/
Traceback (most recent call last):
  File "C:\Users\William-School\AppData\Roaming\Python\Python313\site-packages\django\core\handlers\exception.py", line 55, in inner
    response = get_response(request)
  File "C:\Users\William-School\AppData\Roaming\Python\Python313\site-packages\django\core\handlers\base.py", line 197, in _get_response
    response = wrapped_callback(request, *callback_args, **callback_kwargs)
  File "C:\Users\William-School\AppData\Roaming\Python\Python313\site-packages\django\contrib\auth\decorators.py", line 60, in _view_wrapper
    return view_func(request, *args, **kwargs)
  File "C:\Users\William-School\dev\ssa_project\chipin\views.py", line 72, in group_detail
    user_eligible = request.user.profile.max_spend >= event_share
                    ^^^^^^^^^^^^^^^^^^^^^^^^^^^^^^
AttributeError: 'Profile' object has no attribute 'max_spend'
"GET /chipin/group/6/ HTTP/1.1" 500 72411
Internal Server Error: /chipin/group/6/
Traceback (most recent call last):
  File "C:\Users\William-School\AppData\Roaming\Python\Python313\site-packages\django\db\models\fields\related_descriptors.py", line 512, in __get__
    rel_obj = self.related.get_cached_value(instance)
  File "C:\Users\William-School\AppData\Roaming\Python\Python313\site-packages\django\db\models\fields\mixins.py", line 37, in get_cached_value
    return instance._state.fields_cache[self.cache_name]
           ~~~~~~~~~~~~~~~~~~~~~~~~~~~~^^^^^^^^^^^^^^^^^
KeyError: 'profile'

During handling of the above exception, another exception occurred:

Traceback (most recent call last):
  File "C:\Users\William-School\AppData\Roaming\Python\Python313\site-packages\django\db\backends\utils.py", line 105, in _execute
    return self.cursor.execute(sql, params)
           ~~~~~~~~~~~~~~~~~~~^^^^^^^^^^^^^
  File "C:\Users\William-School\AppData\Roaming\Python\Python313\site-packages\django\db\backends\sqlite3\base.py", line 354, in execute
    return super().execute(query, params)
           ~~~~~~~~~~~~~~~^^^^^^^^^^^^^^^
sqlite3.OperationalError: no such column: users_profile.max_spend

The above exception was the direct cause of the following exception:

Traceback (most recent call last):
  File "C:\Users\William-School\AppData\Roaming\Python\Python313\site-packages\django\core\handlers\exception.py", line 55, in inner
    response = get_response(request)
  File "C:\Users\William-School\AppData\Roaming\Python\Python313\site-packages\django\core\handlers\base.py", line 197, in _get_response
    response = wrapped_callback(request, *callback_args, **callback_kwargs)
  File "C:\Users\William-School\AppData\Roaming\Python\Python313\site-packages\django\contrib\auth\decorators.py", line 60, in _view_wrapper
    return view_func(request, *args, **kwargs)
  File "C:\Users\William-School\dev\ssa_project\chipin\views.py", line 72, in group_detail
    user_eligible = request.user.profile.max_spend >= event_share
                    ^^^^^^^^^^^^^^^^^^^^
  File "C:\Users\William-School\AppData\Roaming\Python\Python313\site-packages\django\utils\functional.py", line 253, in inner
    return func(_wrapped, *args)
  File "C:\Users\William-School\AppData\Roaming\Python\Python313\site-packages\django\db\models\fields\related_descriptors.py", line 520, in __get__
    rel_obj = self.get_queryset(instance=instance).get(**filter_args)
  File "C:\Users\William-School\AppData\Roaming\Python\Python313\site-packages\django\db\models\query.py", line 645, in get
    num = len(clone)
  File "C:\Users\William-School\AppData\Roaming\Python\Python313\site-packages\django\db\models\query.py", line 382, in __len__
    self._fetch_all()
    ~~~~~~~~~~~~~~~^^
  File "C:\Users\William-School\AppData\Roaming\Python\Python313\site-packages\django\db\models\query.py", line 1928, in _fetch_all
    self._result_cache = list(self._iterable_class(self))
                         ~~~~^^^^^^^^^^^^^^^^^^^^^^^^^^^^
  File "C:\Users\William-School\AppData\Roaming\Python\Python313\site-packages\django\db\models\query.py", line 91, in __iter__
    results = compiler.execute_sql(
        chunked_fetch=self.chunked_fetch, chunk_size=self.chunk_size
    )
  File "C:\Users\William-School\AppData\Roaming\Python\Python313\site-packages\django\db\models\sql\compiler.py", line 1574, in execute_sql
    cursor.execute(sql, params)
    ~~~~~~~~~~~~~~^^^^^^^^^^^^^
  File "C:\Users\William-School\AppData\Roaming\Python\Python313\site-packages\django\db\backends\utils.py", line 122, in execute
    return super().execute(sql, params)
           ~~~~~~~~~~~~~~~^^^^^^^^^^^^^
  File "C:\Users\William-School\AppData\Roaming\Python\Python313\site-packages\django\db\backends\utils.py", line 79, in execute
    return self._execute_with_wrappers(
           ~~~~~~~~~~~~~~~~~~~~~~~~~~~^
        sql, params, many=False, executor=self._execute
        ^^^^^^^^^^^^^^^^^^^^^^^^^^^^^^^^^^^^^^^^^^^^^^^
    )
    ^
  File "C:\Users\William-School\AppData\Roaming\Python\Python313\site-packages\django\db\backends\utils.py", line 92, in _execute_with_wrappers
    return executor(sql, params, many, context)
  File "C:\Users\William-School\AppData\Roaming\Python\Python313\site-packages\django\db\backends\utils.py", line 100, in _execute
    with self.db.wrap_database_errors:
         ^^^^^^^^^^^^^^^^^^^^^^^^^^^^
  File "C:\Users\William-School\AppData\Roaming\Python\Python313\site-packages\django\db\utils.py", line 91, in __exit__
    raise dj_exc_value.with_traceback(traceback) from exc_value
  File "C:\Users\William-School\AppData\Roaming\Python\Python313\site-packages\django\db\backends\utils.py", line 105, in _execute
    return self.cursor.execute(sql, params)
           ~~~~~~~~~~~~~~~~~~~^^^^^^^^^^^^^
  File "C:\Users\William-School\AppData\Roaming\Python\Python313\site-packages\django\db\backends\sqlite3\base.py", line 354, in execute
    return super().execute(query, params)
           ~~~~~~~~~~~~~~~^^^^^^^^^^^^^^^
django.db.utils.OperationalError: no such column: users_profile.max_spend
"GET /chipin/group/6/ HTTP/1.1" 500 158432
Internal Server Error: /users/
Traceback (most recent call last):
  File "C:\Users\William-School\AppData\Roaming\Python\Python313\site-packages\django\db\models\fields\related_descriptors.py", line 512, in __get__
    rel_obj = self.related.get_cached_value(instance)
  File "C:\Users\William-School\AppData\Roaming\Python\Python313\site-packages\django\db\models\fields\mixins.py", line 37, in get_cached_value
    return instance._state.fields_cache[self.cache_name]
           ~~~~~~~~~~~~~~~~~~~~~~~~~~~~^^^^^^^^^^^^^^^^^
KeyError: 'profile'

During handling of the above exception, another exception occurred:

Traceback (most recent call last):
  File "C:\Users\William-School\AppData\Roaming\Python\Python313\site-packages\django\db\backends\utils.py", line 105, in _execute
    return self.cursor.execute(sql, params)
           ~~~~~~~~~~~~~~~~~~~^^^^^^^^^^^^^
  File "C:\Users\William-School\AppData\Roaming\Python\Python313\site-packages\django\db\backends\sqlite3\base.py", line 354, in execute
    return super().execute(query, params)
           ~~~~~~~~~~~~~~~^^^^^^^^^^^^^^^
sqlite3.OperationalError: no such column: users_profile.max_spend

The above exception was the direct cause of the following exception:

Traceback (most recent call last):
  File "C:\Users\William-School\AppData\Roaming\Python\Python313\site-packages\django\core\handlers\exception.py", line 55, in inner
    response = get_response(request)
  File "C:\Users\William-School\AppData\Roaming\Python\Python313\site-packages\django\core\handlers\base.py", line 197, in _get_response
    response = wrapped_callback(request, *callback_args, **callback_kwargs)
  File "C:\Users\William-School\AppData\Roaming\Python\Python313\site-packages\django\contrib\auth\decorators.py", line 60, in _view_wrapper
    return view_func(request, *args, **kwargs)
  File "C:\Users\William-School\dev\ssa_project\users\views.py", line 13, in user
    return render(request, "users/user.html")
  File "C:\Users\William-School\AppData\Roaming\Python\Python313\site-packages\django\shortcuts.py", line 25, in render
    content = loader.render_to_string(template_name, context, request, using=using)
  File "C:\Users\William-School\AppData\Roaming\Python\Python313\site-packages\django\template\loader.py", line 62, in render_to_string
    return template.render(context, request)
           ~~~~~~~~~~~~~~~^^^^^^^^^^^^^^^^^^
  File "C:\Users\William-School\AppData\Roaming\Python\Python313\site-packages\django\template\backends\django.py", line 107, in render
    return self.template.render(context)
           ~~~~~~~~~~~~~~~~~~~~^^^^^^^^^
  File "C:\Users\William-School\AppData\Roaming\Python\Python313\site-packages\django\template\base.py", line 169, in render
    with context.bind_template(self):
         ~~~~~~~~~~~~~~~~~~~~~^^^^^^
  File "C:\Program Files\Python313\Lib\contextlib.py", line 141, in __enter__
    return next(self.gen)
  File "C:\Users\William-School\AppData\Roaming\Python\Python313\site-packages\django\template\context.py", line 256, in bind_template
    context = processor(self.request)
  File "C:\Users\William-School\dev\ssa_project\chipin\context_processors.py", line 5, in user_profile
    return {'nickname': request.user.profile.nickname}
                        ^^^^^^^^^^^^^^^^^^^^
  File "C:\Users\William-School\AppData\Roaming\Python\Python313\site-packages\django\utils\functional.py", line 253, in inner
    return func(_wrapped, *args)
  File "C:\Users\William-School\AppData\Roaming\Python\Python313\site-packages\django\db\models\fields\related_descriptors.py", line 520, in __get__
    rel_obj = self.get_queryset(instance=instance).get(**filter_args)
  File "C:\Users\William-School\AppData\Roaming\Python\Python313\site-packages\django\db\models\query.py", line 645, in get
    num = len(clone)
  File "C:\Users\William-School\AppData\Roaming\Python\Python313\site-packages\django\db\models\query.py", line 382, in __len__
    self._fetch_all()
    ~~~~~~~~~~~~~~~^^
  File "C:\Users\William-School\AppData\Roaming\Python\Python313\site-packages\django\db\models\query.py", line 1928, in _fetch_all
    self._result_cache = list(self._iterable_class(self))
                         ~~~~^^^^^^^^^^^^^^^^^^^^^^^^^^^^
  File "C:\Users\William-School\AppData\Roaming\Python\Python313\site-packages\django\db\models\query.py", line 91, in __iter__
    results = compiler.execute_sql(
        chunked_fetch=self.chunked_fetch, chunk_size=self.chunk_size
    )
  File "C:\Users\William-School\AppData\Roaming\Python\Python313\site-packages\django\db\models\sql\compiler.py", line 1574, in execute_sql
    cursor.execute(sql, params)
    ~~~~~~~~~~~~~~^^^^^^^^^^^^^
  File "C:\Users\William-School\AppData\Roaming\Python\Python313\site-packages\django\db\backends\utils.py", line 122, in execute
    return super().execute(sql, params)
           ~~~~~~~~~~~~~~~^^^^^^^^^^^^^
  File "C:\Users\William-School\AppData\Roaming\Python\Python313\site-packages\django\db\backends\utils.py", line 79, in execute
    return self._execute_with_wrappers(
           ~~~~~~~~~~~~~~~~~~~~~~~~~~~^
        sql, params, many=False, executor=self._execute
        ^^^^^^^^^^^^^^^^^^^^^^^^^^^^^^^^^^^^^^^^^^^^^^^
    )
    ^
  File "C:\Users\William-School\AppData\Roaming\Python\Python313\site-packages\django\db\backends\utils.py", line 92, in _execute_with_wrappers
    return executor(sql, params, many, context)
  File "C:\Users\William-School\AppData\Roaming\Python\Python313\site-packages\django\db\backends\utils.py", line 100, in _execute
    with self.db.wrap_database_errors:
         ^^^^^^^^^^^^^^^^^^^^^^^^^^^^
  File "C:\Users\William-School\AppData\Roaming\Python\Python313\site-packages\django\db\utils.py", line 91, in __exit__
    raise dj_exc_value.with_traceback(traceback) from exc_value
  File "C:\Users\William-School\AppData\Roaming\Python\Python313\site-packages\django\db\backends\utils.py", line 105, in _execute
    return self.cursor.execute(sql, params)
           ~~~~~~~~~~~~~~~~~~~^^^^^^^^^^^^^
  File "C:\Users\William-School\AppData\Roaming\Python\Python313\site-packages\django\db\backends\sqlite3\base.py", line 354, in execute
    return super().execute(query, params)
           ~~~~~~~~~~~~~~~^^^^^^^^^^^^^^^
django.db.utils.OperationalError: no such column: users_profile.max_spend
"GET /users/ HTTP/1.1" 500 186087
Internal Server Error: /chipin/
Traceback (most recent call last):
  File "C:\Users\William-School\AppData\Roaming\Python\Python313\site-packages\django\db\models\fields\related_descriptors.py", line 512, in __get__
    rel_obj = self.related.get_cached_value(instance)
  File "C:\Users\William-School\AppData\Roaming\Python\Python313\site-packages\django\db\models\fields\mixins.py", line 37, in get_cached_value
    return instance._state.fields_cache[self.cache_name]
           ~~~~~~~~~~~~~~~~~~~~~~~~~~~~^^^^^^^^^^^^^^^^^
KeyError: 'profile'

During handling of the above exception, another exception occurred:

Traceback (most recent call last):
  File "C:\Users\William-School\AppData\Roaming\Python\Python313\site-packages\django\db\backends\utils.py", line 105, in _execute
    return self.cursor.execute(sql, params)
           ~~~~~~~~~~~~~~~~~~~^^^^^^^^^^^^^
  File "C:\Users\William-School\AppData\Roaming\Python\Python313\site-packages\django\db\backends\sqlite3\base.py", line 354, in execute
    return super().execute(query, params)
           ~~~~~~~~~~~~~~~^^^^^^^^^^^^^^^
sqlite3.OperationalError: no such column: users_profile.max_spend

The above exception was the direct cause of the following exception:

Traceback (most recent call last):
  File "C:\Users\William-School\AppData\Roaming\Python\Python313\site-packages\django\core\handlers\exception.py", line 55, in inner
    response = get_response(request)
  File "C:\Users\William-School\AppData\Roaming\Python\Python313\site-packages\django\core\handlers\base.py", line 197, in _get_response
    response = wrapped_callback(request, *callback_args, **callback_kwargs)
  File "C:\Users\William-School\AppData\Roaming\Python\Python313\site-packages\django\contrib\auth\decorators.py", line 60, in _view_wrapper
    return view_func(request, *args, **kwargs)
  File "C:\Users\William-School\dev\ssa_project\chipin\views.py", line 29, in home
    return render(request, 'chipin/home.html', context)
  File "C:\Users\William-School\AppData\Roaming\Python\Python313\site-packages\django\shortcuts.py", line 25, in render
    content = loader.render_to_string(template_name, context, request, using=using)
  File "C:\Users\William-School\AppData\Roaming\Python\Python313\site-packages\django\template\loader.py", line 62, in render_to_string
    return template.render(context, request)
           ~~~~~~~~~~~~~~~^^^^^^^^^^^^^^^^^^
  File "C:\Users\William-School\AppData\Roaming\Python\Python313\site-packages\django\template\backends\django.py", line 107, in render
    return self.template.render(context)
           ~~~~~~~~~~~~~~~~~~~~^^^^^^^^^
  File "C:\Users\William-School\AppData\Roaming\Python\Python313\site-packages\django\template\base.py", line 169, in render
    with context.bind_template(self):
         ~~~~~~~~~~~~~~~~~~~~~^^^^^^
  File "C:\Program Files\Python313\Lib\contextlib.py", line 141, in __enter__
    return next(self.gen)
  File "C:\Users\William-School\AppData\Roaming\Python\Python313\site-packages\django\template\context.py", line 256, in bind_template
    context = processor(self.request)
  File "C:\Users\William-School\dev\ssa_project\chipin\context_processors.py", line 5, in user_profile
    return {'nickname': request.user.profile.nickname}
                        ^^^^^^^^^^^^^^^^^^^^
  File "C:\Users\William-School\AppData\Roaming\Python\Python313\site-packages\django\utils\functional.py", line 253, in inner
    return func(_wrapped, *args)
  File "C:\Users\William-School\AppData\Roaming\Python\Python313\site-packages\django\db\models\fields\related_descriptors.py", line 520, in __get__
    rel_obj = self.get_queryset(instance=instance).get(**filter_args)
  File "C:\Users\William-School\AppData\Roaming\Python\Python313\site-packages\django\db\models\query.py", line 645, in get
    num = len(clone)
  File "C:\Users\William-School\AppData\Roaming\Python\Python313\site-packages\django\db\models\query.py", line 382, in __len__
    self._fetch_all()
    ~~~~~~~~~~~~~~~^^
  File "C:\Users\William-School\AppData\Roaming\Python\Python313\site-packages\django\db\models\query.py", line 1928, in _fetch_all
    self._result_cache = list(self._iterable_class(self))
                         ~~~~^^^^^^^^^^^^^^^^^^^^^^^^^^^^
  File "C:\Users\William-School\AppData\Roaming\Python\Python313\site-packages\django\db\models\query.py", line 91, in __iter__
    results = compiler.execute_sql(
        chunked_fetch=self.chunked_fetch, chunk_size=self.chunk_size
    )
  File "C:\Users\William-School\AppData\Roaming\Python\Python313\site-packages\django\db\models\sql\compiler.py", line 1574, in execute_sql
    cursor.execute(sql, params)
    ~~~~~~~~~~~~~~^^^^^^^^^^^^^
  File "C:\Users\William-School\AppData\Roaming\Python\Python313\site-packages\django\db\backends\utils.py", line 122, in execute
    return super().execute(sql, params)
           ~~~~~~~~~~~~~~~^^^^^^^^^^^^^
  File "C:\Users\William-School\AppData\Roaming\Python\Python313\site-packages\django\db\backends\utils.py", line 79, in execute
    return self._execute_with_wrappers(
           ~~~~~~~~~~~~~~~~~~~~~~~~~~~^
        sql, params, many=False, executor=self._execute
        ^^^^^^^^^^^^^^^^^^^^^^^^^^^^^^^^^^^^^^^^^^^^^^^
    )
    ^
  File "C:\Users\William-School\AppData\Roaming\Python\Python313\site-packages\django\db\backends\utils.py", line 92, in _execute_with_wrappers
    return executor(sql, params, many, context)
  File "C:\Users\William-School\AppData\Roaming\Python\Python313\site-packages\django\db\backends\utils.py", line 100, in _execute
    with self.db.wrap_database_errors:
         ^^^^^^^^^^^^^^^^^^^^^^^^^^^^
  File "C:\Users\William-School\AppData\Roaming\Python\Python313\site-packages\django\db\utils.py", line 91, in __exit__
    raise dj_exc_value.with_traceback(traceback) from exc_value
  File "C:\Users\William-School\AppData\Roaming\Python\Python313\site-packages\django\db\backends\utils.py", line 105, in _execute
    return self.cursor.execute(sql, params)
           ~~~~~~~~~~~~~~~~~~~^^^^^^^^^^^^^
  File "C:\Users\William-School\AppData\Roaming\Python\Python313\site-packages\django\db\backends\sqlite3\base.py", line 354, in execute
    return super().execute(query, params)
           ~~~~~~~~~~~~~~~^^^^^^^^^^^^^^^
django.db.utils.OperationalError: no such column: users_profile.max_spend
"GET /chipin/ HTTP/1.1" 500 188474
Internal Server Error: /users/
Traceback (most recent call last):
  File "C:\Users\William-School\AppData\Roaming\Python\Python313\site-packages\django\db\models\fields\related_descriptors.py", line 512, in __get__
    rel_obj = self.related.get_cached_value(instance)
  File "C:\Users\William-School\AppData\Roaming\Python\Python313\site-packages\django\db\models\fields\mixins.py", line 37, in get_cached_value
    return instance._state.fields_cache[self.cache_name]
           ~~~~~~~~~~~~~~~~~~~~~~~~~~~~^^^^^^^^^^^^^^^^^
KeyError: 'profile'

During handling of the above exception, another exception occurred:

Traceback (most recent call last):
  File "C:\Users\William-School\AppData\Roaming\Python\Python313\site-packages\django\db\backends\utils.py", line 105, in _execute
    return self.cursor.execute(sql, params)
           ~~~~~~~~~~~~~~~~~~~^^^^^^^^^^^^^
  File "C:\Users\William-School\AppData\Roaming\Python\Python313\site-packages\django\db\backends\sqlite3\base.py", line 354, in execute
    return super().execute(query, params)
           ~~~~~~~~~~~~~~~^^^^^^^^^^^^^^^
sqlite3.OperationalError: no such column: users_profile.max_spend

The above exception was the direct cause of the following exception:

Traceback (most recent call last):
  File "C:\Users\William-School\AppData\Roaming\Python\Python313\site-packages\django\core\handlers\exception.py", line 55, in inner
    response = get_response(request)
  File "C:\Users\William-School\AppData\Roaming\Python\Python313\site-packages\django\core\handlers\base.py", line 197, in _get_response
    response = wrapped_callback(request, *callback_args, **callback_kwargs)
  File "C:\Users\William-School\AppData\Roaming\Python\Python313\site-packages\django\contrib\auth\decorators.py", line 60, in _view_wrapper
    return view_func(request, *args, **kwargs)
  File "C:\Users\William-School\dev\ssa_project\users\views.py", line 13, in user
    return render(request, "users/user.html")
  File "C:\Users\William-School\AppData\Roaming\Python\Python313\site-packages\django\shortcuts.py", line 25, in render
    content = loader.render_to_string(template_name, context, request, using=using)
  File "C:\Users\William-School\AppData\Roaming\Python\Python313\site-packages\django\template\loader.py", line 62, in render_to_string
    return template.render(context, request)
           ~~~~~~~~~~~~~~~^^^^^^^^^^^^^^^^^^
  File "C:\Users\William-School\AppData\Roaming\Python\Python313\site-packages\django\template\backends\django.py", line 107, in render
    return self.template.render(context)
           ~~~~~~~~~~~~~~~~~~~~^^^^^^^^^
  File "C:\Users\William-School\AppData\Roaming\Python\Python313\site-packages\django\template\base.py", line 169, in render
    with context.bind_template(self):
         ~~~~~~~~~~~~~~~~~~~~~^^^^^^
  File "C:\Program Files\Python313\Lib\contextlib.py", line 141, in __enter__
    return next(self.gen)
  File "C:\Users\William-School\AppData\Roaming\Python\Python313\site-packages\django\template\context.py", line 256, in bind_template
    context = processor(self.request)
  File "C:\Users\William-School\dev\ssa_project\chipin\context_processors.py", line 5, in user_profile
    return {'nickname': request.user.profile.nickname}
                        ^^^^^^^^^^^^^^^^^^^^
  File "C:\Users\William-School\AppData\Roaming\Python\Python313\site-packages\django\utils\functional.py", line 253, in inner
    return func(_wrapped, *args)
  File "C:\Users\William-School\AppData\Roaming\Python\Python313\site-packages\django\db\models\fields\related_descriptors.py", line 520, in __get__
    rel_obj = self.get_queryset(instance=instance).get(**filter_args)
  File "C:\Users\William-School\AppData\Roaming\Python\Python313\site-packages\django\db\models\query.py", line 645, in get
    num = len(clone)
  File "C:\Users\William-School\AppData\Roaming\Python\Python313\site-packages\django\db\models\query.py", line 382, in __len__
    self._fetch_all()
    ~~~~~~~~~~~~~~~^^
  File "C:\Users\William-School\AppData\Roaming\Python\Python313\site-packages\django\db\models\query.py", line 1928, in _fetch_all
    self._result_cache = list(self._iterable_class(self))
                         ~~~~^^^^^^^^^^^^^^^^^^^^^^^^^^^^
  File "C:\Users\William-School\AppData\Roaming\Python\Python313\site-packages\django\db\models\query.py", line 91, in __iter__
    results = compiler.execute_sql(
        chunked_fetch=self.chunked_fetch, chunk_size=self.chunk_size
    )
  File "C:\Users\William-School\AppData\Roaming\Python\Python313\site-packages\django\db\models\sql\compiler.py", line 1574, in execute_sql
    cursor.execute(sql, params)
    ~~~~~~~~~~~~~~^^^^^^^^^^^^^
  File "C:\Users\William-School\AppData\Roaming\Python\Python313\site-packages\django\db\backends\utils.py", line 122, in execute
    return super().execute(sql, params)
           ~~~~~~~~~~~~~~~^^^^^^^^^^^^^
  File "C:\Users\William-School\AppData\Roaming\Python\Python313\site-packages\django\db\backends\utils.py", line 79, in execute
    return self._execute_with_wrappers(
           ~~~~~~~~~~~~~~~~~~~~~~~~~~~^
        sql, params, many=False, executor=self._execute
        ^^^^^^^^^^^^^^^^^^^^^^^^^^^^^^^^^^^^^^^^^^^^^^^
    )
    ^
  File "C:\Users\William-School\AppData\Roaming\Python\Python313\site-packages\django\db\backends\utils.py", line 92, in _execute_with_wrappers
    return executor(sql, params, many, context)
  File "C:\Users\William-School\AppData\Roaming\Python\Python313\site-packages\django\db\backends\utils.py", line 100, in _execute
    with self.db.wrap_database_errors:
         ^^^^^^^^^^^^^^^^^^^^^^^^^^^^
  File "C:\Users\William-School\AppData\Roaming\Python\Python313\site-packages\django\db\utils.py", line 91, in __exit__
    raise dj_exc_value.with_traceback(traceback) from exc_value
  File "C:\Users\William-School\AppData\Roaming\Python\Python313\site-packages\django\db\backends\utils.py", line 105, in _execute
    return self.cursor.execute(sql, params)
           ~~~~~~~~~~~~~~~~~~~^^^^^^^^^^^^^
  File "C:\Users\William-School\AppData\Roaming\Python\Python313\site-packages\django\db\backends\sqlite3\base.py", line 354, in execute
    return super().execute(query, params)
           ~~~~~~~~~~~~~~~^^^^^^^^^^^^^^^
django.db.utils.OperationalError: no such column: users_profile.max_spend
"GET /users/ HTTP/1.1" 500 186087
Internal Server Error: /users/
Traceback (most recent call last):
  File "C:\Users\William-School\AppData\Roaming\Python\Python313\site-packages\django\db\models\fields\related_descriptors.py", line 512, in __get__
    rel_obj = self.related.get_cached_value(instance)
  File "C:\Users\William-School\AppData\Roaming\Python\Python313\site-packages\django\db\models\fields\mixins.py", line 37, in get_cached_value
    return instance._state.fields_cache[self.cache_name]
           ~~~~~~~~~~~~~~~~~~~~~~~~~~~~^^^^^^^^^^^^^^^^^
KeyError: 'profile'

During handling of the above exception, another exception occurred:

Traceback (most recent call last):
  File "C:\Users\William-School\AppData\Roaming\Python\Python313\site-packages\django\db\backends\utils.py", line 105, in _execute
    return self.cursor.execute(sql, params)
           ~~~~~~~~~~~~~~~~~~~^^^^^^^^^^^^^
  File "C:\Users\William-School\AppData\Roaming\Python\Python313\site-packages\django\db\backends\sqlite3\base.py", line 354, in execute
    return super().execute(query, params)
           ~~~~~~~~~~~~~~~^^^^^^^^^^^^^^^
sqlite3.OperationalError: no such column: users_profile.max_spend

The above exception was the direct cause of the following exception:

Traceback (most recent call last):
  File "C:\Users\William-School\AppData\Roaming\Python\Python313\site-packages\django\core\handlers\exception.py", line 55, in inner
    response = get_response(request)
  File "C:\Users\William-School\AppData\Roaming\Python\Python313\site-packages\django\core\handlers\base.py", line 197, in _get_response
    response = wrapped_callback(request, *callback_args, **callback_kwargs)
  File "C:\Users\William-School\AppData\Roaming\Python\Python313\site-packages\django\contrib\auth\decorators.py", line 60, in _view_wrapper
    return view_func(request, *args, **kwargs)
  File "C:\Users\William-School\dev\ssa_project\users\views.py", line 13, in user
    return render(request, "users/user.html")
  File "C:\Users\William-School\AppData\Roaming\Python\Python313\site-packages\django\shortcuts.py", line 25, in render
    content = loader.render_to_string(template_name, context, request, using=using)
  File "C:\Users\William-School\AppData\Roaming\Python\Python313\site-packages\django\template\loader.py", line 62, in render_to_string
    return template.render(context, request)
           ~~~~~~~~~~~~~~~^^^^^^^^^^^^^^^^^^
  File "C:\Users\William-School\AppData\Roaming\Python\Python313\site-packages\django\template\backends\django.py", line 107, in render
    return self.template.render(context)
           ~~~~~~~~~~~~~~~~~~~~^^^^^^^^^
  File "C:\Users\William-School\AppData\Roaming\Python\Python313\site-packages\django\template\base.py", line 169, in render
    with context.bind_template(self):
         ~~~~~~~~~~~~~~~~~~~~~^^^^^^
  File "C:\Program Files\Python313\Lib\contextlib.py", line 141, in __enter__
    return next(self.gen)
  File "C:\Users\William-School\AppData\Roaming\Python\Python313\site-packages\django\template\context.py", line 256, in bind_template
    context = processor(self.request)
  File "C:\Users\William-School\dev\ssa_project\chipin\context_processors.py", line 5, in user_profile
    return {'nickname': request.user.profile.nickname}
                        ^^^^^^^^^^^^^^^^^^^^
  File "C:\Users\William-School\AppData\Roaming\Python\Python313\site-packages\django\utils\functional.py", line 253, in inner
    return func(_wrapped, *args)
  File "C:\Users\William-School\AppData\Roaming\Python\Python313\site-packages\django\db\models\fields\related_descriptors.py", line 520, in __get__
    rel_obj = self.get_queryset(instance=instance).get(**filter_args)
  File "C:\Users\William-School\AppData\Roaming\Python\Python313\site-packages\django\db\models\query.py", line 645, in get
    num = len(clone)
  File "C:\Users\William-School\AppData\Roaming\Python\Python313\site-packages\django\db\models\query.py", line 382, in __len__
    self._fetch_all()
    ~~~~~~~~~~~~~~~^^
  File "C:\Users\William-School\AppData\Roaming\Python\Python313\site-packages\django\db\models\query.py", line 1928, in _fetch_all
    self._result_cache = list(self._iterable_class(self))
                         ~~~~^^^^^^^^^^^^^^^^^^^^^^^^^^^^
  File "C:\Users\William-School\AppData\Roaming\Python\Python313\site-packages\django\db\models\query.py", line 91, in __iter__
    results = compiler.execute_sql(
        chunked_fetch=self.chunked_fetch, chunk_size=self.chunk_size
    )
  File "C:\Users\William-School\AppData\Roaming\Python\Python313\site-packages\django\db\models\sql\compiler.py", line 1574, in execute_sql
    cursor.execute(sql, params)
    ~~~~~~~~~~~~~~^^^^^^^^^^^^^
  File "C:\Users\William-School\AppData\Roaming\Python\Python313\site-packages\django\db\backends\utils.py", line 122, in execute
    return super().execute(sql, params)
           ~~~~~~~~~~~~~~~^^^^^^^^^^^^^
  File "C:\Users\William-School\AppData\Roaming\Python\Python313\site-packages\django\db\backends\utils.py", line 79, in execute
    return self._execute_with_wrappers(
           ~~~~~~~~~~~~~~~~~~~~~~~~~~~^
        sql, params, many=False, executor=self._execute
        ^^^^^^^^^^^^^^^^^^^^^^^^^^^^^^^^^^^^^^^^^^^^^^^
    )
    ^
  File "C:\Users\William-School\AppData\Roaming\Python\Python313\site-packages\django\db\backends\utils.py", line 92, in _execute_with_wrappers
    return executor(sql, params, many, context)
  File "C:\Users\William-School\AppData\Roaming\Python\Python313\site-packages\django\db\backends\utils.py", line 100, in _execute
    with self.db.wrap_database_errors:
         ^^^^^^^^^^^^^^^^^^^^^^^^^^^^
  File "C:\Users\William-School\AppData\Roaming\Python\Python313\site-packages\django\db\utils.py", line 91, in __exit__
    raise dj_exc_value.with_traceback(traceback) from exc_value
  File "C:\Users\William-School\AppData\Roaming\Python\Python313\site-packages\django\db\backends\utils.py", line 105, in _execute
    return self.cursor.execute(sql, params)
           ~~~~~~~~~~~~~~~~~~~^^^^^^^^^^^^^
  File "C:\Users\William-School\AppData\Roaming\Python\Python313\site-packages\django\db\backends\sqlite3\base.py", line 354, in execute
    return super().execute(query, params)
           ~~~~~~~~~~~~~~~^^^^^^^^^^^^^^^
django.db.utils.OperationalError: no such column: users_profile.max_spend
"GET /users/ HTTP/1.1" 500 185813
Internal Server Error: /users/register/
Traceback (most recent call last):
  File "C:\Users\William-School\AppData\Roaming\Python\Python313\site-packages\django\db\models\query.py", line 948, in get_or_create
    return self.get(**kwargs), False
           ~~~~~~~~^^^^^^^^^^
  File "C:\Users\William-School\AppData\Roaming\Python\Python313\site-packages\django\db\models\query.py", line 649, in get
    raise self.model.DoesNotExist(
        "%s matching query does not exist." % self.model._meta.object_name
    )
users.models.Profile.DoesNotExist: Profile matching query does not exist.

During handling of the above exception, another exception occurred:

Traceback (most recent call last):
  File "C:\Users\William-School\AppData\Roaming\Python\Python313\site-packages\django\core\handlers\exception.py", line 55, in inner
    response = get_response(request)
  File "C:\Users\William-School\AppData\Roaming\Python\Python313\site-packages\django\core\handlers\base.py", line 197, in _get_response
    response = wrapped_callback(request, *callback_args, **callback_kwargs)
  File "C:\Users\William-School\dev\ssa_project\users\views.py", line 55, in register
    form.save()
    ~~~~~~~~~^^
  File "C:\Users\William-School\dev\ssa_project\users\forms.py", line 22, in save
    user.save()
    ~~~~~~~~~^^
  File "C:\Users\William-School\AppData\Roaming\Python\Python313\site-packages\django\contrib\auth\base_user.py", line 62, in save
    super().save(*args, **kwargs)
    ~~~~~~~~~~~~^^^^^^^^^^^^^^^^^
  File "C:\Users\William-School\AppData\Roaming\Python\Python313\site-packages\django\db\models\base.py", line 891, in save
    self.save_base(
    ~~~~~~~~~~~~~~^
        using=using,
        ^^^^^^^^^^^^
    ...<2 lines>...
        update_fields=update_fields,
        ^^^^^^^^^^^^^^^^^^^^^^^^^^^^
    )
    ^
  File "C:\Users\William-School\AppData\Roaming\Python\Python313\site-packages\django\db\models\base.py", line 1012, in save_base
    post_save.send(
    ~~~~~~~~~~~~~~^
        sender=origin,
        ^^^^^^^^^^^^^^
    ...<4 lines>...
        using=using,
        ^^^^^^^^^^^^
    )
    ^
  File "C:\Users\William-School\AppData\Roaming\Python\Python313\site-packages\django\dispatch\dispatcher.py", line 189, in send
    response = receiver(signal=self, sender=sender, **named)
  File "C:\Users\William-School\dev\ssa_project\users\models.py", line 10, in create_user_profile
    Profile.objects.get_or_create(user=instance)  # Safely create the profile without duplicating
    ~~~~~~~~~~~~~~~~~~~~~~~~~~~~~^^^^^^^^^^^^^^^
  File "C:\Users\William-School\AppData\Roaming\Python\Python313\site-packages\django\db\models\manager.py", line 87, in manager_method
    return getattr(self.get_queryset(), name)(*args, **kwargs)
           ~~~~~~~~~~~~~~~~~~~~~~~~~~~~~~~~~~^^^^^^^^^^^^^^^^^
  File "C:\Users\William-School\AppData\Roaming\Python\Python313\site-packages\django\db\models\query.py", line 955, in get_or_create
    return self.create(**params), True
           ~~~~~~~~~~~^^^^^^^^^^
  File "C:\Users\William-School\AppData\Roaming\Python\Python313\site-packages\django\db\models\query.py", line 679, in create
    obj.save(force_insert=True, using=self.db)
    ~~~~~~~~^^^^^^^^^^^^^^^^^^^^^^^^^^^^^^^^^^
  File "C:\Users\William-School\dev\ssa_project\users\models.py", line 38, in save
    self.clean()
    ~~~~~~~~~~^^
  File "C:\Users\William-School\dev\ssa_project\users\models.py", line 35, in clean
    validate_unique_nickname(self.nickname, instance=self)
    ~~~~~~~~~~~~~~~~~~~~~~~~^^^^^^^^^^^^^^^^^^^^^^^^^^^^^^
  File "C:\Users\William-School\dev\ssa_project\users\models.py", line 21, in validate_unique_nickname
    raise ValidationError(f"Nickname '{nickname}' is already taken.")
django.core.exceptions.ValidationError: ["Nickname '' is already taken."]
"POST /users/register/ HTTP/1.1" 500 130629
Internal Server Error: /users/register/
Traceback (most recent call last):
  File "C:\Users\William-School\AppData\Roaming\Python\Python313\site-packages\django\db\models\query.py", line 948, in get_or_create
    return self.get(**kwargs), False
           ~~~~~~~~^^^^^^^^^^
  File "C:\Users\William-School\AppData\Roaming\Python\Python313\site-packages\django\db\models\query.py", line 649, in get
    raise self.model.DoesNotExist(
        "%s matching query does not exist." % self.model._meta.object_name
    )
users.models.Profile.DoesNotExist: Profile matching query does not exist.

During handling of the above exception, another exception occurred:

Traceback (most recent call last):
  File "C:\Users\William-School\AppData\Roaming\Python\Python313\site-packages\django\core\handlers\exception.py", line 55, in inner
    response = get_response(request)
  File "C:\Users\William-School\AppData\Roaming\Python\Python313\site-packages\django\core\handlers\base.py", line 197, in _get_response
    response = wrapped_callback(request, *callback_args, **callback_kwargs)
  File "C:\Users\William-School\dev\ssa_project\users\views.py", line 55, in register
    form.save()
    ~~~~~~~~~^^
  File "C:\Users\William-School\dev\ssa_project\users\forms.py", line 22, in save
    user.save()
    ~~~~~~~~~^^
  File "C:\Users\William-School\AppData\Roaming\Python\Python313\site-packages\django\contrib\auth\base_user.py", line 62, in save
    super().save(*args, **kwargs)
    ~~~~~~~~~~~~^^^^^^^^^^^^^^^^^
  File "C:\Users\William-School\AppData\Roaming\Python\Python313\site-packages\django\db\models\base.py", line 891, in save
    self.save_base(
    ~~~~~~~~~~~~~~^
        using=using,
        ^^^^^^^^^^^^
    ...<2 lines>...
        update_fields=update_fields,
        ^^^^^^^^^^^^^^^^^^^^^^^^^^^^
    )
    ^
  File "C:\Users\William-School\AppData\Roaming\Python\Python313\site-packages\django\db\models\base.py", line 1012, in save_base
    post_save.send(
    ~~~~~~~~~~~~~~^
        sender=origin,
        ^^^^^^^^^^^^^^
    ...<4 lines>...
        using=using,
        ^^^^^^^^^^^^
    )
    ^
  File "C:\Users\William-School\AppData\Roaming\Python\Python313\site-packages\django\dispatch\dispatcher.py", line 189, in send
    response = receiver(signal=self, sender=sender, **named)
  File "C:\Users\William-School\dev\ssa_project\users\models.py", line 10, in create_user_profile
    Profile.objects.get_or_create(user=instance)  # Safely create the profile without duplicating
    ~~~~~~~~~~~~~~~~~~~~~~~~~~~~~^^^^^^^^^^^^^^^
  File "C:\Users\William-School\AppData\Roaming\Python\Python313\site-packages\django\db\models\manager.py", line 87, in manager_method
    return getattr(self.get_queryset(), name)(*args, **kwargs)
           ~~~~~~~~~~~~~~~~~~~~~~~~~~~~~~~~~~^^^^^^^^^^^^^^^^^
  File "C:\Users\William-School\AppData\Roaming\Python\Python313\site-packages\django\db\models\query.py", line 955, in get_or_create
    return self.create(**params), True
           ~~~~~~~~~~~^^^^^^^^^^
  File "C:\Users\William-School\AppData\Roaming\Python\Python313\site-packages\django\db\models\query.py", line 679, in create
    obj.save(force_insert=True, using=self.db)
    ~~~~~~~~^^^^^^^^^^^^^^^^^^^^^^^^^^^^^^^^^^
  File "C:\Users\William-School\dev\ssa_project\users\models.py", line 38, in save
    self.clean()
    ~~~~~~~~~~^^
  File "C:\Users\William-School\dev\ssa_project\users\models.py", line 35, in clean
    validate_unique_nickname(self.nickname, instance=self)
    ~~~~~~~~~~~~~~~~~~~~~~~~^^^^^^^^^^^^^^^^^^^^^^^^^^^^^^
  File "C:\Users\William-School\dev\ssa_project\users\models.py", line 21, in validate_unique_nickname
    raise ValidationError(f"Nickname '{nickname}' is already taken.")
django.core.exceptions.ValidationError: ["Nickname '' is already taken."]
"POST /users/register/ HTTP/1.1" 500 130647
